Workbook

Sheet Параметры
A1: Параметры (жёлтые ячейки можно менять — все расчёты пересчитаются)
A3: Команд в I туре | B3: 20 | C3: Со слов организатора: 20 команд по 3 участника
A4: Команд во II туре | B4: 10 | C4: Со слов организатора: во II тур проходят 10 команд
A5: Команд в III туре | B5: 3 | C5: Со слов организатора: в III тур проходят 3 команды
A6: Запас расходного материала | B6: 0.1 | C6: Допущение: 10% на брак и ошибки
A9: Обозначения:
A10: Синий шрифт на жёлтом фоне — вводимые значения (можно менять)
A11: Чёрный шрифт — формулы (не трогать)
A12: Источник конкурсов, ответственных, инструментов и шовного материала: «Программа олимпиады по хирургии 2026»
A13: Количество там, где регламент его не указывает, — допущение (помечено в столбце «Примечание»)

Sheet Конкурсы
A1: Внутривузовская студенческая олимпиада по хирургии им. проф. А.П. Кошеля — конкурсы, ответственные, расходный материал, волонтёры
A3: № | B3: Тур | C3: Конкурс | D3: Ответственные за конкурс | E3: Команд | F3: Время выполнения | G3: Биоматериал / препарат | H3: Шовный материал (на 1 команду) | I3: Прочий расходный материал (на 1 команду) | J3: Макеты и оснащение | K3: Инструменты (на 1 рабочее место, многоразовые) | L3: Количество волонтёров | M3: Задачи волонтёров
A4: I тур — 6 ноября 2026
A5: 1 | B5: 1 тур | C5: Абдоминальная хирургия | D5: Сулеймен Жусип Барашкова Анастасия | E5: =Параметры!$B$3 -> 20 | F5: 60 мин (стоп-время 80 мин) | G5: • Органокомплекс свиной (желудок + тонкая кишка 20 см) — 1 шт | H5: • ПГА/викрил USP 4/0, атравм. колющая игла — 2 шт • ПГА/викрил USP 3/0, атравм. колющая игла — 2 шт • ПГА/викрил USP 2/0, атравм. колющая игла — 1 шт | I5: • Лезвие для скальпеля №23/24 — 1 шт • Перчатки смотровые нестерильные — 3 пара | J5: • Пенополистирол (основа для фиксации препарата) — 1 шт • Бокс глубиной 10–15 см — 1 шт | K5: Иглодержатель — 1 пинцет анатомический — 2 ножницы Купера/Метценбаума — 1 кишечный жом эластичный — 4 ручка для скальпеля — 1 зажим «москит»/Бильрот — 2 | L5: 4 | M5: Раздача препаратов, хронометраж по каждой команде, уборка столов
A6: 2 | B6: 1 тур | C6: Сосудистый шов | D6: Попов Никита Вавилов Данила | E6: =Параметры!$B$3 -> 20 | F6: 80 мин (стоп-время 100 мин) | G6: • Аорта свиная — 1 шт • Кондуит из большой подкожной вены — 1 шт | H6: • Prolene/монофил USP 4/0, две атравм. иглы — 2 шт • Prolene/монофил USP 6/0, две атравм. иглы — 1 шт | I6: • Протез кровеносного сосуда INTERGARD 18 мм — 1 шт • Лезвие для скальпеля остроконечное №11 — 1 шт • Перчатки смотровые нестерильные — 3 пара | J6: • Муляж сердца — 1 шт • Контейнер — имитация грудной полости — 1 шт | K6: Зажим Сатинского — 1 зажим «бульдог» — 1 пинцет сосудистый — 2 иглодержатель сосудистый — 1 ножницы сосудистые — 1 скальпель остроконечный — 1 зажим Холстеда «москит» с сегментами микроирригатора | L6: 4 | M6: Подготовка контейнеров и муляжей сердца, хронометраж, уборка
A7: 3 | B7: 1 тур | C7: Торакальная хирургия | D7: Ахмедова Малика | E7: =Параметры!$B$3 -> 20 | F7: 60 мин (стоп-время 75 мин) | G7: • Трахея (свиная) — 1 шт | H7: • Викрил/PDS USP 2/0–3/0, атравм. игла — 3 шт | I7: • Лезвие для скальпеля — 1 шт • Перчатки смотровые нестерильные — 3 пара | J7: • Макет: пластиковая бутылка с окном 5–7 см, выстланная поролоном — 1 шт • Подставка из пеноплекса — 1 шт | K7: Скальпель — 1 иглодержатель — 1 пинцет анатомический — 2 зажим Бильрот — 2 зажим «москит» — 4 | L7: 3 | M7: Установка макетов, разметка участка стеноза, хронометраж
A8: 4 | B8: 1 тур | C8: Наложение сухожильного шва | D8: Гунзынов Дамдин Бегадилла Бекарыс | E8: =Параметры!$B$3 -> 20 | F8: 50 мин | G8: • Сухожилие бычье — 1 шт | H8: • Лавсан/капрон/этибонд USP 1 — 2 шт • Монофил USP 4/0 — 1 шт | I8: • Игла травматическая — 1 шт • Лезвие для скальпеля брюшистое — 1 шт • Перчатки смотровые нестерильные — 3 пара | J8: — | K8: Зажим «москит» — 2 скальпель брюшистый — 1 иглодержатель — 1 пинцет анатомический — 1 пинцет хирургический — 1 | L8: 3 | M8: Раздача сухожилий, хронометраж, уборка
A9: 5 | B9: 1 тур | C9: Реконструктивно-пластическая хирургия. Первый этап | D9: Грибанова Белла Имтоссими Георгий | E9: =Параметры!$B$3 -> 20 | F9: 30 мин | G9: • Курица (кожный лоскут спинки тушки) — 1 шт | H9: • Prolene/монофил USP 4/0, атравм. колющая игла — 1 шт • Prolene/монофил USP 5/0, атравм. колющая игла — 1 шт | I9: • Лезвие для скальпеля — 1 шт • Маркер хирургический — 1 шт • Сантиметровая лента — 1 шт • Перчатки смотровые нестерильные — 3 пара | J9: — | K9: Иглодержатель — 1 пинцет анатомический — 4 ножницы — 1 скальпель — 1 | L9: 3 | M9: Жеребьёвка лоскутов, хронометраж, помощь жюри с замерами соска
A10: 6 | B10: 1 тур | C10: Вязание хирургических узлов | D10: Бабина Кристина | E10: =Параметры!$B$3 -> 20 | F10: 30 сек на участника | G10: — | H10: • Капрон USP 1, нить 60 см — 3 шт | I10: • Перчатки смотровые нестерильные — 3 пара • Зубочистки (проверка плотности узла) — 3 шт | J10: — | K10: Не требуются | L10: 4 | M10: «Палец» для завязывания (держит нить), хронометраж 30 сек, проверка плотности зубочисткой, замер «косички»
A11: II тур — 7 ноября 2026
A12: 7 | B12: 2 тур | C12: Травматология | D12: Ибрагимов Фазли Гунзынов Дамдин | E12: =Параметры!$B$4 -> 10 | F12: 15 мин + 5 мин на рентгенограммы | G12: — | H12: — | I12: • Гипсовый бинт 15 см — 2 шт • Бинт марлевый нестерильный — 2 шт • Салфетки марлевые — 1 уп • Ватные прокладки — 1 уп • Шприц — 1 шт • Перчатки смотровые нестерильные — 3 пара | J12: — | K12: Ножницы ёмкость для воды | L12: 3 | M12: Подготовка воды и гипса, хронометраж, уборка гипса
A13: 8 | B13: 2 тур | C13: Оперативная урология | D13: Бакушина Софья Абаимов Иван | E13: =Параметры!$B$4 -> 10 | F13: 60 мин (+ бонус за время) | G13: • Мочевой пузырь с уретрой и мочеточником — 1 шт • Куриное бедро (имитация m. psoas) — 1 шт | H13: • ПГА USP 5/0, одна атравм. колющая игла — 1 шт • ПГА USP 4/0, одна атравм. колющая игла — 2 шт • ПГА USP 3/0, одна атравм. колющая игла — 2 шт • Prolene/монофил USP 4/0, атравм. колющая игла — 1 шт | I13: • Мочеточниковый катетер — 1 шт • Лезвие для скальпеля — 1 шт • Перчатки смотровые нестерильные — 3 пара | J13: — | K13: Скальпель — 1 иглодержатель общехирургический — 1 пинцет анатомический — 2 ножницы — 1 зажим Холстеда «москит» прямой — 1 | L13: 3 | M13: Хронометраж и фиксация места по времени (для бонуса), проверка герметичности
A14: 9 | B14: 2 тур | C14: Реконструктивно-пластическая хирургия. Второй этап | D14: Грибанова Белла Имтоссими Георгий | E14: =Параметры!$B$4 -> 10 | F14: 80 мин | G14: • Куриная грудка с хрящевой частью грудины — 1 шт | H14: • Prolene/монофил USP 4/0, атравм. колющая игла — 1 шт • Prolene/монофил USP 5/0, атравм. колющая игла — 1 шт | I14: • Марля (накрыть препарат) — 1 м • Лезвие для скальпеля — 1 шт • Маркер хирургический — 1 шт • Сантиметровая лента — 1 шт • Перчатки смотровые нестерильные — 3 пара | J14: — | K14: Иглодержатель — 1 пинцет анатомический — 4 ножницы — 1 скальпель — 1 | L14: 3 | M14: Раздача препаратов под влажной марлей, хронометраж, уборка
A15: 10 | B15: 2 тур | C15: Оперативная гинекология | D15: Устюжанина Ольга Корнеева Алина | E15: =Параметры!$B$4 -> 10 | F15: 45 мин (после 50 мин — 0 за время) | G15: • Кишка свиная толстая/прямая, отрезок 10–15 см — 2 шт • Курица (тушка для фиксации комплекса) — 1 шт | H15: • Vicryl/ПГА USP 3/0 — 2 шт • Vicryl/ПГА USP 2/0 — 1 шт | I15: • Лезвие для скальпеля №10 — 1 шт • Перчатки смотровые нестерильные — 3 пара | J15: — | K15: Зеркало Куско — 1 крючки Фарабефа — 2 пуговчатый зонд — 1 скальпель №10 — 1 ножницы Купера — 1 пинцет анатомический — 2 зажим «москит» — 1 иглодержатель Гегара — 1 | L15: 3 | M15: Подготовка комплексов в тушках, хронометраж, уборка
A16: III тур — 8 ноября 2026
A17: 11 | B17: 3 тур | C17: Сегментарная резекция толстой кишки с анастомозом конец в конец на экспериментальном животном | D17: Сулеймен Жусип Барашкова Анастасия | E17: =Параметры!$B$5 -> 3 | F17: 90 мин | G17: • Кролик (экспериментальное животное) — 1 шт | H17: • ПГА USP 3/0–4/0, атравм. игла, 45 см — 5 шт • Лавсан USP 2/0–0, атравм. игла, 45 см — 5 шт | I17: • Новокаин (блокада брыжейки) — 2 амп • Хлоргексидин / антисептик — 1 фл • Шприц — 2 шт • Халат операционный стерильный — 3 шт • Перчатки хирургические стерильные — 3 пара • Перчатки смотровые нестерильные — 4 пара • Шапочка медицинская — 4 шт • Маска медицинская — 4 шт • Простыня стерильная клеящаяся — 1 шт • Операционное бельё (простыни для стола) — 1 компл • Бинт марлевый (вязки для фиксации) — 4 шт • Мешок для отходов класса Б — 1 шт • Лезвие для скальпеля — 1 шт | J17: • Планка ДСП с отверстиями — 1 шт | K17: Бельевые цапки — 4 корнцанг — 1 иглодержатель — 1 пинцеты анатомический и хирургический — 2 ножницы Купера/Метценбаума — 2 кишечный жом Кохера — 2 Г-образный зажим — 1 скальпель — 1 зажим Бильрота — 2 зажим Кохера — 2 зажим «москит» — 2 крючки Фарабефа — 1 зажим Микулича — 4 машинка для стрижки | L17: 5 | M17: По регламенту 1 санитар на бригаду от организаторов (3) + 2 на хронометраж и утилизацию отходов
K18: Итого волонтёров на все конкурсы: | L18: =L5+L6+L7+L8+L9+L10+L12+L13+L14+L15+L17 -> 38
K19: в т.ч. в 1 тур (6 ноября 2026): | L19: =L5+L6+L7+L8+L9+L10 -> 21
K20: в т.ч. в 2 тур (7 ноября 2026): | L20: =L12+L13+L14+L15 -> 12
K21: в т.ч. в 3 тур (8 ноября 2026): | L21: =L17 -> 5
A23: Количество волонтёров — предложение, не из регламента: поменяйте жёлтые ячейки, итог пересчитается. Количество на закупку — на листе «Расходный материал».

Sheet Расходный материал
A1: Расходный материал по конкурсам: на 1 команду × число команд в туре + запас
A3: Тур | B3: № | C3: Конкурс | D3: Наименование | E3: Категория | F3: Ед. | G3: На 1 команду | H3: Команд | I3: Итого с запасом | J3: Примечание
A4: 1 | B4: 1 | C4: Абдоминальная хирургия | D4: Органокомплекс свиной (желудок + тонкая кишка 20 см) | E4: Биоматериал | F4: шт | G4: 1 | H4: =Параметры!$B$3 -> 20 | I4: =ROUNDUP(G4*H4*(1+Параметры!$B$6),0) -> 22
A5: 1 | B5: 1 | C5: Абдоминальная хирургия | D5: Пенополистирол (основа для фиксации препарата) | E5: Макет/оснащение | F5: шт | G5: 1 | H5: =Параметры!$B$3 -> 20 | I5: =ROUNDUP(G5*H5*(1+Параметры!$B$6),0) -> 22
A6: 1 | B6: 1 | C6: Абдоминальная хирургия | D6: Бокс глубиной 10–15 см | E6: Макет/оснащение | F6: шт | G6: 1 | H6: =Параметры!$B$3 -> 20 | I6: =ROUNDUP(G6*H6*(1+Параметры!$B$6),0) -> 22 | J6: многоразовый
A7: 1 | B7: 1 | C7: Абдоминальная хирургия | D7: ПГА/викрил USP 4/0, атравм. колющая игла | E7: Шовный материал | F7: шт | G7: 2 | H7: =Параметры!$B$3 -> 20 | I7: =ROUNDUP(G7*H7*(1+Параметры!$B$6),0) -> 44 | J7: допущение: в регламенте количество не указано
A8: 1 | B8: 1 | C8: Абдоминальная хирургия | D8: ПГА/викрил USP 3/0, атравм. колющая игла | E8: Шовный материал | F8: шт | G8: 2 | H8: =Параметры!$B$3 -> 20 | I8: =ROUNDUP(G8*H8*(1+Параметры!$B$6),0) -> 44 | J8: допущение: в регламенте количество не указано
A9: 1 | B9: 1 | C9: Абдоминальная хирургия | D9: ПГА/викрил USP 2/0, атравм. колющая игла | E9: Шовный материал | F9: шт | G9: 1 | H9: =Параметры!$B$3 -> 20 | I9: =ROUNDUP(G9*H9*(1+Параметры!$B$6),0) -> 22 | J9: допущение: в регламенте количество не указано
A10: 1 | B10: 1 | C10: Абдоминальная хирургия | D10: Лезвие для скальпеля №23/24 | E10: Расходник | F10: шт | G10: 1 | H10: =Параметры!$B$3 -> 20 | I10: =ROUNDUP(G10*H10*(1+Параметры!$B$6),0) -> 22
A11: 1 | B11: 1 | C11: Абдоминальная хирургия | D11: Перчатки смотровые нестерильные | E11: Расходник | F11: пара | G11: 3 | H11: =Параметры!$B$3 -> 20 | I11: =ROUNDUP(G11*H11*(1+Параметры!$B$6),0) -> 66 | J11: по 1 паре на участника
A12: 1 | B12: 2 | C12: Сосудистый шов | D12: Аорта свиная | E12: Биоматериал | F12: шт | G12: 1 | H12: =Параметры!$B$3 -> 20 | I12: =ROUNDUP(G12*H12*(1+Параметры!$B$6),0) -> 22
A13: 1 | B13: 2 | C13: Сосудистый шов | D13: Кондуит из большой подкожной вены | E13: Биоматериал | F13: шт | G13: 1 | H13: =Параметры!$B$3 -> 20 | I13: =ROUNDUP(G13*H13*(1+Параметры!$B$6),0) -> 22
A14: 1 | B14: 2 | C14: Сосудистый шов | D14: Протез кровеносного сосуда INTERGARD 18 мм | E14: Расходник | F14: шт | G14: 1 | H14: =Параметры!$B$3 -> 20 | I14: =ROUNDUP(G14*H14*(1+Параметры!$B$6),0) -> 22
A15: 1 | B15: 2 | C15: Сосудистый шов | D15: Муляж сердца | E15: Макет/оснащение | F15: шт | G15: 1 | H15: =Параметры!$B$3 -> 20 | I15: =ROUNDUP(G15*H15*(1+Параметры!$B$6),0) -> 22 | J15: многоразовый
A16: 1 | B16: 2 | C16: Сосудистый шов | D16: Контейнер — имитация грудной полости | E16: Макет/оснащение | F16: шт | G16: 1 | H16: =Параметры!$B$3 -> 20 | I16: =ROUNDUP(G16*H16*(1+Параметры!$B$6),0) -> 22 | J16: многоразовый
A17: 1 | B17: 2 | C17: Сосудистый шов | D17: Prolene/монофил USP 4/0, две атравм. иглы | E17: Шовный материал | F17: шт | G17: 2 | H17: =Параметры!$B$3 -> 20 | I17: =ROUNDUP(G17*H17*(1+Параметры!$B$6),0) -> 44
A18: 1 | B18: 2 | C18: Сосудистый шов | D18: Prolene/монофил USP 6/0, две атравм. иглы | E18: Шовный материал | F18: шт | G18: 1 | H18: =Параметры!$B$3 -> 20 | I18: =ROUNDUP(G18*H18*(1+Параметры!$B$6),0) -> 22
A19: 1 | B19: 2 | C19: Сосудистый шов | D19: Лезвие для скальпеля остроконечное №11 | E19: Расходник | F19: шт | G19: 1 | H19: =Параметры!$B$3 -> 20 | I19: =ROUNDUP(G19*H19*(1+Параметры!$B$6),0) -> 22
A20: 1 | B20: 2 | C20: Сосудистый шов | D20: Перчатки смотровые нестерильные | E20: Расходник | F20: пара | G20: 3 | H20: =Параметры!$B$3 -> 20 | I20: =ROUNDUP(G20*H20*(1+Параметры!$B$6),0) -> 66 | J20: по 1 паре на участника
A21: 1 | B21: 3 | C21: Торакальная хирургия | D21: Трахея (свиная) | E21: Биоматериал | F21: шт | G21: 1 | H21: =Параметры!$B$3 -> 20 | I21: =ROUNDUP(G21*H21*(1+Параметры!$B$6),0) -> 22
A22: 1 | B22: 3 | C22: Торакальная хирургия | D22: Макет: пластиковая бутылка с окном 5–7 см, выстланная поролоном | E22: Макет/оснащение | F22: шт | G22: 1 | H22: =Параметры!$B$3 -> 20 | I22: =ROUNDUP(G22*H22*(1+Параметры!$B$6),0) -> 22
A23: 1 | B23: 3 | C23: Торакальная хирургия | D23: Подставка из пеноплекса | E23: Макет/оснащение | F23: шт | G23: 1 | H23: =Параметры!$B$3 -> 20 | I23: =ROUNDUP(G23*H23*(1+Параметры!$B$6),0) -> 22
A24: 1 | B24: 3 | C24: Торакальная хирургия | D24: Викрил/PDS USP 2/0–3/0, атравм. игла | E24: Шовный материал | F24: шт | G24: 3 | H24: =Параметры!$B$3 -> 20 | I24: =ROUNDUP(G24*H24*(1+Параметры!$B$6),0) -> 66
A25: 1 | B25: 3 | C25: Торакальная хирургия | D25: Лезвие для скальпеля | E25: Расходник | F25: шт | G25: 1 | H25: =Параметры!$B$3 -> 20 | I25: =ROUNDUP(G25*H25*(1+Параметры!$B$6),0) -> 22
A26: 1 | B26: 3 | C26: Торакальная хирургия | D26: Перчатки смотровые нестерильные | E26: Расходник | F26: пара | G26: 3 | H26: =Параметры!$B$3 -> 20 | I26: =ROUNDUP(G26*H26*(1+Параметры!$B$6),0) -> 66 | J26: по 1 паре на участника
A27: 1 | B27: 4 | C27: Наложение сухожильного шва | D27: Сухожилие бычье | E27: Биоматериал | F27: шт | G27: 1 | H27: =Параметры!$B$3 -> 20 | I27: =ROUNDUP(G27*H27*(1+Параметры!$B$6),0) -> 22
A28: 1 | B28: 4 | C28: Наложение сухожильного шва | D28: Лавсан/капрон/этибонд USP 1 | E28: Шовный материал | F28: шт | G28: 2 | H28: =Параметры!$B$3 -> 20 | I28: =ROUNDUP(G28*H28*(1+Параметры!$B$6),0) -> 44
A29: 1 | B29: 4 | C29: Наложение сухожильного шва | D29: Монофил USP 4/0 | E29: Шовный материал | F29: шт | G29: 1 | H29: =Параметры!$B$3 -> 20 | I29: =ROUNDUP(G29*H29*(1+Параметры!$B$6),0) -> 22
A30: 1 | B30: 4 | C30: Наложение сухожильного шва | D30: Игла травматическая | E30: Расходник | F30: шт | G30: 1 | H30: =Параметры!$B$3 -> 20 | I30: =ROUNDUP(G30*H30*(1+Параметры!$B$6),0) -> 22
A31: 1 | B31: 4 | C31: Наложение сухожильного шва | D31: Лезвие для скальпеля брюшистое | E31: Расходник | F31: шт | G31: 1 | H31: =Параметры!$B$3 -> 20 | I31: =ROUNDUP(G31*H31*(1+Параметры!$B$6),0) -> 22
A32: 1 | B32: 4 | C32: Наложение сухожильного шва | D32: Перчатки смотровые нестерильные | E32: Расходник | F32: пара | G32: 3 | H32: =Параметры!$B$3 -> 20 | I32: =ROUNDUP(G32*H32*(1+Параметры!$B$6),0) -> 66 | J32: по 1 паре на участника
A33: 1 | B33: 5 | C33: Реконструктивно-пластическая хирургия. Первый этап | D33: Курица (кожный лоскут спинки тушки) | E33: Биоматериал | F33: шт | G33: 1 | H33: =Параметры!$B$3 -> 20 | I33: =ROUNDUP(G33*H33*(1+Параметры!$B$6),0) -> 22
A34: 1 | B34: 5 | C34: Реконструктивно-пластическая хирургия. Первый этап | D34: Prolene/монофил USP 4/0, атравм. колющая игла | E34: Шовный материал | F34: шт | G34: 1 | H34: =Параметры!$B$3 -> 20 | I34: =ROUNDUP(G34*H34*(1+Параметры!$B$6),0) -> 22 | J34: допущение: в регламенте количество не указано
A35: 1 | B35: 5 | C35: Реконструктивно-пластическая хирургия. Первый этап | D35: Prolene/монофил USP 5/0, атравм. колющая игла | E35: Шовный материал | F35: шт | G35: 1 | H35: =Параметры!$B$3 -> 20 | I35: =ROUNDUP(G35*H35*(1+Параметры!$B$6),0) -> 22 | J35: допущение: в регламенте количество не указано
A36: 1 | B36: 5 | C36: Реконструктивно-пластическая хирургия. Первый этап | D36: Лезвие для скальпеля | E36: Расходник | F36: шт | G36: 1 | H36: =Параметры!$B$3 -> 20 | I36: =ROUNDUP(G36*H36*(1+Параметры!$B$6),0) -> 22
A37: 1 | B37: 5 | C37: Реконструктивно-пластическая хирургия. Первый этап | D37: Маркер хирургический | E37: Расходник | F37: шт | G37: 1 | H37: =Параметры!$B$3 -> 20 | I37: =ROUNDUP(G37*H37*(1+Параметры!$B$6),0) -> 22
A38: 1 | B38: 5 | C38: Реконструктивно-пластическая хирургия. Первый этап | D38: Сантиметровая лента | E38: Расходник | F38: шт | G38: 1 | H38: =Параметры!$B$3 -> 20 | I38: =ROUNDUP(G38*H38*(1+Параметры!$B$6),0) -> 22
A39: 1 | B39: 5 | C39: Реконструктивно-пластическая хирургия. Первый этап | D39: Перчатки смотровые нестерильные | E39: Расходник | F39: пара | G39: 3 | H39: =Параметры!$B$3 -> 20 | I39: =ROUNDUP(G39*H39*(1+Параметры!$B$6),0) -> 66 | J39: по 1 паре на участника
A40: 1 | B40: 6 | C40: Вязание хирургических узлов | D40: Капрон USP 1, нить 60 см | E40: Шовный материал | F40: шт | G40: 3 | H40: =Параметры!$B$3 -> 20 | I40: =ROUNDUP(G40*H40*(1+Параметры!$B$6),0) -> 66 | J40: по 1 нити на участника
A41: 1 | B41: 6 | C41: Вязание хирургических узлов | D41: Перчатки смотровые нестерильные | E41: Расходник | F41: пара | G41: 3 | H41: =Параметры!$B$3 -> 20 | I41: =ROUNDUP(G41*H41*(1+Параметры!$B$6),0) -> 66 | J41: по 1 паре на участника
...

Sheet Закупка итого
A1: Сводный список закупки: одинаковые позиции из всех конкурсов сложены
A3: Наименование | B3: Категория | C3: Ед. | D3: Итого к закупке | E3: Цена за ед. | F3: Сумма
A4: Аорта свиная | B4: Биоматериал | C4: шт | D4: =SUMIFS('Расходный материал'!$I$4:$I$99,'Расходный материал'!$D$4:$D$99,A4,'Расходный материал'!$F$4:$F$99,C4) -> 22 | F4: =D4*E4 -> 0
A5: Кишка свиная толстая/прямая, отрезок 10–15 см | B5: Биоматериал | C5: шт | D5: =SUMIFS('Расходный материал'!$I$4:$I$99,'Расходный материал'!$D$4:$D$99,A5,'Расходный материал'!$F$4:$F$99,C5) -> 22 | F5: =D5*E5 -> 0
A6: Кондуит из большой подкожной вены | B6: Биоматериал | C6: шт | D6: =SUMIFS('Расходный материал'!$I$4:$I$99,'Расходный материал'!$D$4:$D$99,A6,'Расходный материал'!$F$4:$F$99,C6) -> 22 | F6: =D6*E6 -> 0
A7: Кролик (экспериментальное животное) | B7: Биоматериал | C7: шт | D7: =SUMIFS('Расходный материал'!$I$4:$I$99,'Расходный материал'!$D$4:$D$99,A7,'Расходный материал'!$F$4:$F$99,C7) -> 4 | F7: =D7*E7 -> 0
A8: Куриная грудка с хрящевой частью грудины | B8: Биоматериал | C8: шт | D8: =SUMIFS('Расходный материал'!$I$4:$I$99,'Расходный материал'!$D$4:$D$99,A8,'Расходный материал'!$F$4:$F$99,C8) -> 11 | F8: =D8*E8 -> 0
A9: Куриное бедро (имитация m. psoas) | B9: Биоматериал | C9: шт | D9: =SUMIFS('Расходный материал'!$I$4:$I$99,'Расходный материал'!$D$4:$D$99,A9,'Расходный материал'!$F$4:$F$99,C9) -> 11 | F9: =D9*E9 -> 0
A10: Курица (кожный лоскут спинки тушки) | B10: Биоматериал | C10: шт | D10: =SUMIFS('Расходный материал'!$I$4:$I$99,'Расходный материал'!$D$4:$D$99,A10,'Расходный материал'!$F$4:$F$99,C10) -> 22 | F10: =D10*E10 -> 0
A11: Курица (тушка для фиксации комплекса) | B11: Биоматериал | C11: шт | D11: =SUMIFS('Расходный материал'!$I$4:$I$99,'Расходный материал'!$D$4:$D$99,A11,'Расходный материал'!$F$4:$F$99,C11) -> 11 | F11: =D11*E11 -> 0
A12: Мочевой пузырь с уретрой и мочеточником | B12: Биоматериал | C12: шт | D12: =SUMIFS('Расходный материал'!$I$4:$I$99,'Расходный материал'!$D$4:$D$99,A12,'Расходный материал'!$F$4:$F$99,C12) -> 11 | F12: =D12*E12 -> 0
A13: Органокомплекс свиной (желудок + тонкая кишка 20 см) | B13: Биоматериал | C13: шт | D13: =SUMIFS('Расходный материал'!$I$4:$I$99,'Расходный материал'!$D$4:$D$99,A13,'Расходный материал'!$F$4:$F$99,C13) -> 22 | F13: =D13*E13 -> 0
A14: Сухожилие бычье | B14: Биоматериал | C14: шт | D14: =SUMIFS('Расходный материал'!$I$4:$I$99,'Расходный материал'!$D$4:$D$99,A14,'Расходный материал'!$F$4:$F$99,C14) -> 22 | F14: =D14*E14 -> 0
A15: Трахея (свиная) | B15: Биоматериал | C15: шт | D15: =SUMIFS('Расходный материал'!$I$4:$I$99,'Расходный материал'!$D$4:$D$99,A15,'Расходный материал'!$F$4:$F$99,C15) -> 22 | F15: =D15*E15 -> 0
... A77: Секундомеры | B77: Общее | C77: шт | D77: =SUMIFS('Расходный материал'!$I$4:$I$99,'Расходный материал'!$D$4:$D$99,A77,'Расходный материал'!$F$4:$F$99,C77) -> 10 | F77: =D77*E77 -> 0
E78: Итого: | F78: =SUM(F4:F77) -> 0
A80: Впишите цены в жёлтый столбец — суммы посчитаются автоматически. Цены указывайте в одной валюте за единицу из столбца «Ед.».
